<robot name="AL5D_arm">

	<link name="base_link">
	</link>
	<link name="link1">
	</link>
	<link name="link2">
	</link>
	<link name="link3">
	</link>
	<link name="link4">
	</link>
	<link name="link5">
	</link>


	<joint name="joint0" type="fixed">
		<parent link="base_link"/>
		<child link="link1"/>
		<origin rpy="0 0 0" xyz="0 0 0"/>
	</joint>
	<joint name="joint1" type="revolute">
		<parent link="link1"/>
		<child link="link2"/>
		<origin rpy="0 0 0" xyz="0 0 0.6985"/>
		<axis xyz="0 1 0" />
		<limit lower="-1.5708" upper="1.5708" ></limit>
	</joint>
	<joint name="joint2" type="revolute">
		<parent link="link2"/>
		<child link="link3"/>
		<origin rpy="0 0 0" xyz="1.4605 0 0"/>
		<axis xyz="0 1 0" />
		<limit lower="-1.5708" upper="1.5708" ></limit>
	</joint>
	<joint name="joint3" type="revolute">
		<parent link="link3"/>
		<child link="link4"/>
		<origin rpy="0 0 0" xyz="1.87325 0 0"/>
		<axis xyz="0 1 0" />
		<limit lower="-1.5708" upper="1.5708"></limit>
	</joint>
	<joint name="joint4" type="revolute">
		<parent link="link4"/>
		<child link="link5"/>
		<origin rpy="0 0 0" xyz="0.85725 0 0"/>
		<axis xyz="0 1 0" />
		<limit lower="-1.5708" upper="1.5708" ></limit>
	</joint>
</robot>
